Workbook

Sheet Media Plan Template
E1: ELECTION WEEK? | F1: YES | G1: ELECTION: | H1: PRIMARY
E2: END DATE | F2: 46329 | G2: CLIENT TYPE: | H2: CANDIDATE | L2: {=INDEX($2:$2, COLUMN()+1)+1} -> 12 | M2: {=INDEX($2:$2, COLUMN()+1)+1} -> 11 | N2: {=INDEX($2:$2, COLUMN()+1)+1} -> 10 | O2: {=INDEX($2:$2, COLUMN()+1)+1} -> 9 | P2: {=INDEX($2:$2, COLUMN()+1)+1} -> 8 | Q2: {=INDEX($2:$2, COLUMN()+1)+1} -> 7 | R2: {=INDEX($2:$2, COLUMN()+1)+1} -> 6 | S2: {=INDEX($2:$2, COLUMN()+1)+1} -> 5 | ... V2: {=INDEX($2:$2, COLUMN()+1)+1} -> 2 | W2: 1
E3: START DATE | F3: =F2-83 -> 46246 | G3: COMMISSION% | H3: 0.15 | L3: =L4-6 -> 46245 | M3: =M4-6 -> 46252 | N3: =N4-6 -> 46259 | O3: =O4-6 -> 46266 | P3: =P4-6 -> 46273 | Q3: =Q4-6 -> 46280 | R3: =R4-6 -> 46287 | S3: =S4-6 -> 46294 | ... V3: =V4-6 -> 46315 | W3: =IF(F1="YES",W4-7,W4-6) -> 46322
E4: WINDOW DATE (AUTO GENERATED) | F4: =IF(H2<>"CANDIDATE","N/A", IF(H1="PRIMARY",F2-45, IF(H1="GENERAL",F2-60,"N/A"))) -> 46284 | G4: LENGTH | H4: =DATEDIF(F3,F2,"D")+1 & " D / " & ROUND((DATEDIF(F3,F2,"D")/7),0) & " W" -> 84 D / 12 W | L4: {=INDEX($3:$3, COLUMN()+1)-1} -> 46251 | M4: {=INDEX($3:$3, COLUMN()+1)-1} -> 46258 | N4: {=INDEX($3:$3, COLUMN()+1)-1} -> 46265 | O4: {=INDEX($3:$3, COLUMN()+1)-1} -> 46272 | P4: {=INDEX($3:$3, COLUMN()+1)-1} -> 46279 | Q4: {=INDEX($3:$3, COLUMN()+1)-1} -> 46286 | R4: {=INDEX($3:$3, COLUMN()+1)-1} -> 46293 | S4: {=INDEX($3:$3, COLUMN()+1)-1} -> 46300 | ... V4: {=INDEX($3:$3, COLUMN()+1)-1} -> 46321 | W4: =F2 -> 46329
A6: MEDIA PLAN TEMPLATE | AB6: CLIENT LOGO
A7: 2026 | S7: Absentee Ballot Drop xx/xx | T7: Early In-person Voting Begins xx/xx
A8: Estimated Q3 OOW A35+ CPP | B8: Estimated Q3 IW A35+ CPP | C8: Estimated Early Q4 A35+ CPP | D8: Estimated Late Q4 A35+ CPP | E8: Broadcast TV | F8: % of District Vote by DMA (add source) | J8: AD SERVING | L8: =CONCATENATE("Week ",L$2) -> Week 12 | M8: =CONCATENATE("Week ",M$2) -> Week 11 | N8: =CONCATENATE("Week ",N$2) -> Week 10 | O8: =CONCATENATE("Week ",O$2) -> Week 9 | P8: =CONCATENATE("Week ",P$2) -> Week 8 | Q8: =CONCATENATE("Week ",Q$2) -> Week 7 | R8: =CONCATENATE("Week ",R$2) -> Week 6 | S8: =CONCATENATE("Week ",S$2) -> Week 5 | ... W8: =CONCATENATE("Week ",W$2) -> Week 1 | Y8: Total | AA8: % of Broadcast | AB8: % of Plan
L9: =TEXT(L$3, "mmm d") & " - " & TEXT(L$4, "mmm d") -> Aug 11 - Aug 17 | M9: =TEXT(M$3, "mmm d") & " - " & TEXT(M$4, "mmm d") -> Aug 18 - Aug 24 | N9: =TEXT(N$3, "mmm d") & " - " & TEXT(N$4, "mmm d") -> Aug 25 - Aug 31 | O9: =TEXT(O$3, "mmm d") & " - " & TEXT(O$4, "mmm d") -> Sep 1 - Sep 7 | P9: =TEXT(P$3, "mmm d") & " - " & TEXT(P$4, "mmm d") -> Sep 8 - Sep 14 | Q9: =TEXT(Q$3, "mmm d") & " - " & TEXT(Q$4, "mmm d") -> Sep 15 - Sep 21 | R9: =TEXT(R$3, "mmm d") & " - " & TEXT(R$4, "mmm d") -> Sep 22 - Sep 28 | S9: =TEXT(S$3, "mmm d") & " - " & TEXT(S$4, "mmm d") -> Sep 29 - Oct 5 | ... W9: =TEXT(W$3, "mmm d") & " - " & TEXT(W$4, "mmm d") -> Oct 27 - Nov 3
H10: Points / Week | J10: N/A | L10: 0 | M10: 0 | N10: 0 | O10: 0 | P10: 0 | Q10: 0 | R10: 0 | S10: 0 | T10: 0 | U10: 0 | V10: 0 | W10: 0 | Y10: =SUM(L10:W10) -> 0 | AA10: =IFERROR($Y11/$Y$55, 0) -> 0 | AB10: =IFERROR($Y11/$Y$398, 0) -> 0
A11: 100 | B11: 200 | C11: 300 | D11: 400 | E11: Market A | H11: $$$ | L11: =$A11*L10 -> 0 | M11: =$B11*M10 -> 0 | N11: =$B11*N10 -> 0 | O11: =$B11*O10 -> 0 | P11: =$B11*P10 -> 0 | Q11: =$B11*Q10 -> 0 | R11: =$B11*R10 -> 0 | S11: =$C11*S10 -> 0 | T11: =$C11*T10 -> 0 | U11: =$C11*U10 -> 0 | V11: =$D11*V10 -> 0 | W11: =$D11*W10 -> 0 | Y11: =SUM(L11:W11) -> 0
H12: Points / Week | J12: N/A | L12: 0 | M12: 0 | N12: 0 | O12: 0 | P12: 0 | Q12: 0 | R12: 0 | S12: 0 | T12: 0 | U12: 0 | V12: 0 | W12: 0 | Y12: =SUM(L12:W12) -> 0 | AA12: =IFERROR($Y13/$Y$55, 0) -> 0 | AB12: =IFERROR($Y13/$Y$398, 0) -> 0
A13: 100 | B13: 200 | C13: 300 | D13: 400 | E13: Market B | H13: $$$ | L13: =$A13*L12 -> 0 | M13: =$B13*M12 -> 0 | N13: =$B13*N12 -> 0 | O13: =$B13*O12 -> 0 | P13: =$B13*P12 -> 0 | Q13: =$B13*Q12 -> 0 | R13: =$B13*R12 -> 0 | S13: =$C13*S12 -> 0 | T13: =$C13*T12 -> 0 | U13: =$C13*U12 -> 0 | V13: =$D13*V12 -> 0 | W13: =$D13*W12 -> 0 | Y13: =SUM(L13:W13) -> 0
H14: Points / Week | J14: N/A | L14: 0 | M14: 0 | N14: 0 | O14: 0 | P14: 0 | Q14: 0 | R14: 0 | S14: 0 | T14: 0 | U14: 0 | V14: 0 | W14: 0 | Y14: =SUM(L14:W14) -> 0 | AA14: =IFERROR($Y15/$Y$55, 0) -> 0 | AB14: =IFERROR($Y15/$Y$398, 0) -> 0
A15: 100 | B15: 200 | C15: 300 | D15: 400 | E15: Market C | H15: $$$ | L15: =$A15*L14 -> 0 | M15: =$B15*M14 -> 0 | N15: =$B15*N14 -> 0 | O15: =$B15*O14 -> 0 | P15: =$B15*P14 -> 0 | Q15: =$B15*Q14 -> 0 | R15: =$B15*R14 -> 0 | S15: =$C15*S14 -> 0 | T15: =$C15*T14 -> 0 | U15: =$C15*U14 -> 0 | V15: =$D15*V14 -> 0 | W15: =$D15*W14 -> 0 | Y15: =SUM(L15:W15) -> 0
H16: Points / Week | J16: N/A | L16: 0 | M16: 0 | N16: 0 | O16: 0 | P16: 0 | Q16: 0 | R16: 0 | S16: 0 | T16: 0 | U16: 0 | V16: 0 | W16: 0 | Y16: =SUM(L16:W16) -> 0 | AA16: =IFERROR($Y17/$Y$55, 0) -> 0 | AB16: =IFERROR($Y17/$Y$398, 0) -> 0
A17: 100 | B17: 200 | C17: 300 | D17: 400 | E17: Market D | H17: $$$ | L17: =$A17*L16 -> 0 | M17: =$B17*M16 -> 0 | N17: =$B17*N16 -> 0 | O17: =$B17*O16 -> 0 | P17: =$B17*P16 -> 0 | Q17: =$B17*Q16 -> 0 | R17: =$B17*R16 -> 0 | S17: =$C17*S16 -> 0 | T17: =$C17*T16 -> 0 | U17: =$C17*U16 -> 0 | V17: =$D17*V16 -> 0 | W17: =$D17*W16 -> 0 | Y17: =SUM(L17:W17) -> 0
H18: Points / Week | J18: N/A | L18: 0 | M18: 0 | N18: 0 | O18: 0 | P18: 0 | Q18: 0 | R18: 0 | S18: 0 | T18: 0 | U18: 0 | V18: 0 | W18: 0 | Y18: =SUM(L18:W18) -> 0 | AA18: =IFERROR($Y19/$Y$55, 0) -> 0 | AB18: =IFERROR($Y19/$Y$398, 0) -> 0
A19: 100 | B19: 200 | C19: 300 | D19: 400 | E19: Market E | H19: $$$ | L19: =$A19*L18 -> 0 | M19: =$B19*M18 -> 0 | N19: =$B19*N18 -> 0 | O19: =$B19*O18 -> 0 | P19: =$B19*P18 -> 0 | Q19: =$B19*Q18 -> 0 | R19: =$B19*R18 -> 0 | S19: =$C19*S18 -> 0 | T19: =$C19*T18 -> 0 | U19: =$C19*U18 -> 0 | V19: =$D19*V18 -> 0 | W19: =$D19*W18 -> 0 | Y19: =SUM(L19:W19) -> 0
H20: Points / Week | J20: N/A | L20: 0 | M20: 0 | N20: 0 | O20: 0 | P20: 0 | Q20: 0 | R20: 0 | S20: 0 | T20: 0 | U20: 0 | V20: 0 | W20: 0 | Y20: =SUM(L20:W20) -> 0 | AA20: =IFERROR($Y21/$Y$55, 0) -> 0 | AB20: =IFERROR($Y21/$Y$398, 0) -> 0
A21: 100 | B21: 200 | C21: 300 | D21: 400 | E21: Market F | H21: $$$ | L21: =$A21*L20 -> 0 | M21: =$B21*M20 -> 0 | N21: =$B21*N20 -> 0 | O21: =$B21*O20 -> 0 | P21: =$B21*P20 -> 0 | Q21: =$B21*Q20 -> 0 | R21: =$B21*R20 -> 0 | S21: =$C21*S20 -> 0 | T21: =$C21*T20 -> 0 | U21: =$C21*U20 -> 0 | V21: =$D21*V20 -> 0 | W21: =$D21*W20 -> 0 | Y21: =SUM(L21:W21) -> 0
E23: English-Language Broadcast Subtotal | H23: Subtotal | L23: =SUMIF($H$9:$H$24,"$$$",L$9:L$24) -> 0 | M23: =SUMIF($H$9:$H$24,"$$$",M$9:M$24) -> 0 | N23: =SUMIF($H$9:$H$24,"$$$",N$9:N$24) -> 0 | O23: =SUMIF($H$9:$H$24,"$$$",O$9:O$24) -> 0 | P23: =SUMIF($H$9:$H$24,"$$$",P$9:P$24) -> 0 | Q23: =SUMIF($H$9:$H$24,"$$$",Q$9:Q$24) -> 0 | R23: =SUMIF($H$9:$H$24,"$$$",R$9:R$24) -> 0 | S23: =SUMIF($H$9:$H$24,"$$$",S$9:S$24) -> 0 | ... W23: =SUMIF($H$9:$H$24,"$$$",W$9:W$24) -> 0 | Y23: =SUM(L23:W23) -> 0 | AA23: =IFERROR($Y23/$Y$55, 0) -> 0 | AB23: =IFERROR($Y23/$Y$398, 0) -> 0
A24: Estimated Q3 OOW H25+ CPP | B24: Estimated Q3 IW H25+ CPP | C24: Estimated Early Q4 H25+ CPP | D24: Estimated Late Q4 H25+ CPP | E24: Spanish-Language TV | F24: % DMA Hispanic
H25: Points / Week | J25: N/A | L25: 0 | M25: 0 | N25: 0 | O25: 0 | P25: 0 | Q25: 0 | R25: 0 | S25: 0 | T25: 0 | U25: 0 | V25: 0 | W25: 0 | Y25: =SUM(L25:W25) -> 0 | AA25: =IFERROR($Y26/$Y$55, 0) -> 0 | AB25: =IFERROR($Y26/$Y$398, 0) -> 0
A26: 100 | B26: 100 | C26: 100 | D26: 200 | E26: Market A | H26: $$$ | L26: =$A26*L25 -> 0 | M26: =$B26*M25 -> 0 | N26: =$B26*N25 -> 0 | O26: =$B26*O25 -> 0 | P26: =$B26*P25 -> 0 | Q26: =$B26*Q25 -> 0 | R26: =$B26*R25 -> 0 | S26: =$C26*S25 -> 0 | T26: =$C26*T25 -> 0 | U26: =$C26*U25 -> 0 | V26: =$D26*V25 -> 0 | W26: =$D26*W25 -> 0 | Y26: =SUM(L26:W26) -> 0
H27: Points / Week | J27: N/A | L27: 0 | M27: 0 | N27: 0 | O27: 0 | P27: 0 | Q27: 0 | R27: 0 | S27: 0 | T27: 0 | U27: 0 | V27: 0 | W27: 0 | Y27: =SUM(L27:W27) -> 0 | AA27: =IFERROR($Y28/$Y$55, 0) -> 0 | AB27: =IFERROR($Y28/$Y$398, 0) -> 0
A28: 100 | B28: 100 | C28: 100 | D28: 200 | E28: Market B | H28: $$$ | L28: =$A28*L27 -> 0 | M28: =$B28*M27 -> 0 | N28: =$B28*N27 -> 0 | O28: =$B28*O27 -> 0 | P28: =$B28*P27 -> 0 | Q28: =$B28*Q27 -> 0 | R28: =$B28*R27 -> 0 | S28: =$C28*S27 -> 0 | T28: =$C28*T27 -> 0 | U28: =$C28*U27 -> 0 | V28: =$D28*V27 -> 0 | W28: =$D28*W27 -> 0 | Y28: =SUM(L28:W28) -> 0
H29: Points / Week | J29: N/A | L29: 0 | M29: 0 | N29: 0 | O29: 0 | P29: 0 | Q29: 0 | R29: 0 | S29: 0 | T29: 0 | U29: 0 | V29: 0 | W29: 0 | Y29: =SUM(L29:W29) -> 0 | AA29: =IFERROR($Y30/$Y$55, 0) -> 0 | AB29: =IFERROR($Y30/$Y$398, 0) -> 0
A30: 100 | B30: 100 | C30: 100 | D30: 200 | E30: Market C | H30: $$$ | L30: =$A30*L29 -> 0 | M30: =$B30*M29 -> 0 | N30: =$B30*N29 -> 0 | O30: =$B30*O29 -> 0 | P30: =$B30*P29 -> 0 | Q30: =$B30*Q29 -> 0 | R30: =$B30*R29 -> 0 | S30: =$C30*S29 -> 0 | T30: =$C30*T29 -> 0 | U30: =$C30*U29 -> 0 | V30: =$D30*V29 -> 0 | W30: =$D30*W29 -> 0 | Y30: =SUM(L30:W30) -> 0
H31: Points / Week | J31: N/A | L31: 0 | M31: 0 | N31: 0 | O31: 0 | P31: 0 | Q31: 0 | R31: 0 | S31: 0 | T31: 0 | U31: 0 | V31: 0 | W31: 0 | Y31: =SUM(L31:W31) -> 0 | AA31: =IFERROR($Y32/$Y$55, 0) -> 0 | AB31: =IFERROR($Y32/$Y$398, 0) -> 0
A32: 100 | B32: 100 | C32: 100 | D32: 200 | E32: Market D | H32: $$$ | L32: =$A32*L31 -> 0 | M32: =$B32*M31 -> 0 | N32: =$B32*N31 -> 0 | O32: =$B32*O31 -> 0 | P32: =$B32*P31 -> 0 | Q32: =$B32*Q31 -> 0 | R32: =$B32*R31 -> 0 | S32: =$C32*S31 -> 0 | T32: =$C32*T31 -> 0 | U32: =$C32*U31 -> 0 | V32: =$D32*V31 -> 0 | W32: =$D32*W31 -> 0 | Y32: =SUM(L32:W32) -> 0
H33: Points / Week | J33: N/A | L33: 0 | M33: 0 | N33: 0 | O33: 0 | P33: 0 | Q33: 0 | R33: 0 | S33: 0 | T33: 0 | U33: 0 | V33: 0 | W33: 0 | Y33: =SUM(L33:W33) -> 0 | AA33: =IFERROR($Y34/$Y$55, 0) -> 0 | AB33: =IFERROR($Y34/$Y$398, 0) -> 0
A34: 100 | B34: 100 | C34: 100 | D34: 200 | E34: Market E | H34: $$$ | L34: =$A34*L33 -> 0 | M34: =$B34*M33 -> 0 | N34: =$B34*N33 -> 0 | O34: =$B34*O33 -> 0 | P34: =$B34*P33 -> 0 | Q34: =$B34*Q33 -> 0 | R34: =$B34*R33 -> 0 | S34: =$C34*S33 -> 0 | T34: =$C34*T33 -> 0 | U34: =$C34*U33 -> 0 | V34: =$D34*V33 -> 0 | W34: =$D34*W33 -> 0 | Y34: =SUM(L34:W34) -> 0
H35: Points / Week | J35: N/A | L35: 0 | M35: 0 | N35: 0 | O35: 0 | P35: 0 | Q35: 0 | R35: 0 | S35: 0 | T35: 0 | U35: 0 | V35: 0 | W35: 0 | Y35: =SUM(L35:W35) -> 0 | AA35: =IFERROR($Y36/$Y$55, 0) -> 0 | AB35: =IFERROR($Y36/$Y$398, 0) -> 0
A36: 100 | B36: 100 | C36: 100 | D36: 200 | E36: Market F | H36: $$$ | L36: =$A36*L35 -> 0 | M36: =$B36*M35 -> 0 | N36: =$B36*N35 -> 0 | O36: =$B36*O35 -> 0 | P36: =$B36*P35 -> 0 | Q36: =$B36*Q35 -> 0 | R36: =$B36*R35 -> 0 | S36: =$C36*S35 -> 0 | T36: =$C36*T35 -> 0 | U36: =$C36*U35 -> 0 | V36: =$D36*V35 -> 0 | W36: =$D36*W35 -> 0 | Y36: =SUM(L36:W36) -> 0
E38: Spanish-Language Broadcast Subtotal | H38: Subtotal | L38: =SUMIF($H$24:$H$39,"$$$",L$24:L$39) -> 0 | M38: =SUMIF($H$24:$H$39,"$$$",M$24:M$39) -> 0 | N38: =SUMIF($H$24:$H$39,"$$$",N$24:N$39) -> 0 | O38: =SUMIF($H$24:$H$39,"$$$",O$24:O$39) -> 0 | P38: =SUMIF($H$24:$H$39,"$$$",P$24:P$39) -> 0 | Q38: =SUMIF($H$24:$H$39,"$$$",Q$24:Q$39) -> 0 | R38: =SUMIF($H$24:$H$39,"$$$",R$24:R$39) -> 0 | S38: =SUMIF($H$24:$H$39,"$$$",S$24:S$39) -> 0 | ... W38: =SUMIF($H$24:$H$39,"$$$",W$24:W$39) -> 0 | Y38: =SUM(L38:W38) -> 0 | AA38: =IFERROR($Y38/$Y$55, 0) -> 0 | AB38: =IFERROR($Y38/$Y$398, 0) -> 0
A39: CPS | E39: Broadcast Sports | F39: Network / Channel
H40: Points / Week | J40: N/A | L40: 0 | M40: 0 | N40: 0 | O40: 0 | P40: 0 | Q40: 0 | R40: 0 | S40: 0 | T40: 0 | U40: 0 | V40: 0 | W40: 0 | Y40: =SUM(L40:W40) -> 0 | AA40: =IFERROR($Y41/$Y$55, 0) -> 0 | AB40: =IFERROR($Y41/$Y$398, 0) -> 0
A41: 100 | E41: Team / Game / League | H41: $$$ | L41: =$A41*L40 -> 0 | M41: =$A41*M40 -> 0 | N41: =$A41*N40 -> 0 | O41: =$A41*O40 -> 0 | P41: =$A41*P40 -> 0 | Q41: =$A41*Q40 -> 0 | R41: =$A41*R40 -> 0 | S41: =$A41*S40 -> 0 | ... W41: =$A41*W40 -> 0 | Y41: =SUM(L41:W41) -> 0
H42: Points / Week | J42: N/A | L42: 0 | M42: 0 | N42: 0 | O42: 0 | P42: 0 | Q42: 0 | R42: 0 | S42: 0 | T42: 0 | U42: 0 | V42: 0 | W42: 0 | Y42: =SUM(L42:W42) -> 0 | AA42: =IFERROR($Y43/$Y$55, 0) -> 0 | AB42: =IFERROR($Y43/$Y$398, 0) -> 0
A43: 100 | E43: Team / Game / League | H43: $$$ | L43: =$A43*L42 -> 0 | M43: =$A43*M42 -> 0 | N43: =$A43*N42 -> 0 | O43: =$A43*O42 -> 0 | P43: =$A43*P42 -> 0 | Q43: =$A43*Q42 -> 0 | R43: =$A43*R42 -> 0 | S43: =$A43*S42 -> 0 | ... W43: =$A43*W42 -> 0 | Y43: =SUM(L43:W43) -> 0
...

Sheet Digital Targeting
A1: GEOGRAPHY | B1: AUDIENCE | C1: Languages | D1: Ad Serving Calculator
A2: USA | B2: Healthcare Engaged | C2: English | H2: =G2/21 -> 0
B3: Test | C3: Spanish | D3: Budget to Cut | E3: Media CPM | F3: Serving CPM | G3: Gross To Cut
D4: 0.39 | E4: 47.06 | F4: 0.55 | G4: =(E4/(E4+F4))*D4 -> 0.38549464 | H4: =G4/21 -> 0.018356888
G19: 7 | H19: 8 | I19: 9 | J19: 10 | K19: 11 | L19: 12 | M19: 13
G20: COVERAGE ESTIMATES
A21: Search Key - Do Not Delete Column | B21: Geo | C21: Audience Name | D21: Language | E21: List Size (if applicable) | F21: URL | G21: TV Streaming Aggregate | H21: YouTube | I21: YouTube TV | J21: Meta | K21: Audio Aggregate | L21: VOD | M21: Digital
A22: =IF(OR(D22="", LOWER(D22)="english"), B22 & " - " & C22, B22 & " - " & C22 & " (" & D22 & ")" ) -> USA - Healthcare Engaged | B22: USA | C22: Healthcare Engaged | D22: English | E22: 66994200 | G22: 0.79 | H22: 0.59 | I22: 0.04 | J22: 0.58 | K22: 0.63 | L22: 0.91 | M22: 0.88
A23: =IF(OR(D23="", LOWER(D23)="english"), B23 & " - " & C23, B23 & " - " & C23 & " (" & D23 & ")" ) -> USA - Test | B23: USA | C23: Test | D23: English | E23: 100000 | G23: 0.8 | H23: 0.5 | I23: 0.05 | J23: 0.75 | K23: 0.4 | L23: 0.8 | M23: 0.7
A24: =IF(OR(D24="", LOWER(D24)="english"), B24 & " - " & C24, B24 & " - " & C24 & " (" & D24 & ")" ) -> - | D24: English
A25: =IF(OR(D25="", LOWER(D25)="english"), B25 & " - " & C25, B25 & " - " & C25 & " (" & D25 & ")" ) -> - | D25: English
A26: =IF(OR(D26="", LOWER(D26)="english"), B26 & " - " & C26, B26 & " - " & C26 & " (" & D26 & ")" ) -> - | D26: English
A27: =IF(OR(D27="", LOWER(D27)="english"), B27 & " - " & C27, B27 & " - " & C27 & " (" & D27 & ")" ) -> - | D27: English
A28: =IF(OR(D28="", LOWER(D28)="english"), B28 & " - " & C28, B28 & " - " & C28 & " (" & D28 & ")" ) -> - | D28: English
A29: =IF(OR(D29="", LOWER(D29)="english"), B29 & " - " & C29, B29 & " - " & C29 & " (" & D29 & ")" ) -> - | D29: English
A30: =IF(OR(D30="", LOWER(D30)="english"), B30 & " - " & C30, B30 & " - " & C30 & " (" & D30 & ")" ) -> - | D30: English
A31: =IF(OR(D31="", LOWER(D31)="english"), B31 & " - " & C31, B31 & " - " & C31 & " (" & D31 & ")" ) -> - | D31: English
A32: =IF(OR(D32="", LOWER(D32)="english"), B32 & " - " & C32, B32 & " - " & C32 & " (" & D32 & ")" ) -> - | D32: English
A33: =IF(OR(D33="", LOWER(D33)="english"), B33 & " - " & C33, B33 & " - " & C33 & " (" & D33 & ")" ) -> - | D33: English
A34: =IF(OR(D34="", LOWER(D34)="english"), B34 & " - " & C34, B34 & " - " & C34 & " (" & D34 & ")" ) -> - | D34: English
A35: =IF(OR(D35="", LOWER(D35)="english"), B35 & " - " & C35, B35 & " - " & C35 & " (" & D35 & ")" ) -> - | D35: English
... A66: =IF(OR(D66="", LOWER(D66)="english"), B66 & " - " & C66, B66 & " - " & C66 & " (" & D66 & ")" ) -> - | D66: English
A67: =IF(OR(D67="", LOWER(D67)="english"), B67 & " - " & C67, B67 & " - " & C67 & " (" & D67 & ")" ) -> -
A68: =IF(OR(D68="", LOWER(D68)="english"), B68 & " - " & C68, B68 & " - " & C68 & " (" & D68 & ")" ) -> -
A69: =IF(OR(D69="", LOWER(D69)="english"), B69 & " - " & C69, B69 & " - " & C69 & " (" & D69 & ")" ) -> -
A70: =IF(OR(D70="", LOWER(D70)="english"), B70 & " - " & C70, B70 & " - " & C70 & " (" & D70 & ")" ) -> -
A71: =IF(OR(D71="", LOWER(D71)="english"), B71 & " - " & C71, B71 & " - " & C71 & " (" & D71 & ")" ) -> -
A522: If data update is needed: drag broken formula down over values that are present. Then copy and paste as values and return to no fill. (YELLOW CELLS) | D522: LAST UPDATED 3/2/26
A524: =[1]CPMs!$A1 -> SEARCH KEY DRAG | B524: =[1]CPMs!$G1 -> INPUT DRAG | C524: =[1]CPMs!$F1 -> CPM DRAG | D524: DO NOT DRAG THESE
A525: SEARCH KEY | B525: INPUT OPTION | C525: CPM (GROSS) | D525: CPM Modifier (MANUAL) | E525: CPM
A526: The Trade DeskCTV/OTT (0:06s) | B526: The Trade Desk - CTV/OTT (0:06s) | C526: 41.18 | D526: 1 | E526: =C526*D526 -> 41.18
A527: The Trade DeskCTV/OTT (0:15s) | B527: The Trade Desk - CTV/OTT (0:15s) | C527: 47.06 | D527: 1 | E527: =C527*D527 -> 47.06
A528: The Trade DeskCTV/OTT (0:30s) | B528: The Trade Desk - CTV/OTT (0:30s) | C528: 47.06 | D528: 1 | E528: =C528*D528 -> 47.06
A529: The Trade DeskCTV/OTT (0:60s) | B529: The Trade Desk - CTV/OTT (0:60s) | C529: 47.06 | D529: 1 | E529: =C529*D529 -> 47.06
A530: The Trade DeskCTV/OTT (0:90s) | B530: The Trade Desk - CTV/OTT (0:90s) | C530: 58.82 | D530: 1 | E530: =C530*D530 -> 58.82
A531: The Trade DeskOLV (0:06s) | B531: The Trade Desk - OLV (0:06s) | C531: 17.65 | D531: 1 | E531: =C531*D531 -> 17.65
A532: The Trade DeskOLV (0:15s) | B532: The Trade Desk - OLV (0:15s) | C532: 17.65 | D532: 1 | E532: =C532*D532 -> 17.65
A533: The Trade DeskOLV (0:30s) | B533: The Trade Desk - OLV (0:30s) | C533: 17.65 | D533: 1 | E533: =C533*D533 -> 17.65
A534: The Trade DeskOLV (0:60s) | B534: The Trade Desk - OLV (0:60s) | C534: 17.65 | D534: 1 | E534: =C534*D534 -> 17.65
A535: The Trade DeskOLV (0:90s) | B535: The Trade Desk - OLV (0:90s) | C535: 17.65 | D535: 1 | E535: =C535*D535 -> 17.65
...
